Workbook

Sheet Calculadora
B1: CALCULADORA DE PREÇOS esDEV
B2: Preenche apenas as células amarelas. Tudo o resto é calculado.
B4: 1. CARACTERÍSTICAS DO PROJETO
B5: Cliente / Projeto | C5: Cliente / Nome do projeto
B6: Tipo de projeto | C6: Website institucional (até 5 páginas) | D6: Define as horas base de cada fase.
B7: Nível de complexidade | C7: Média — padrão de mercado
B8: Nº de páginas / ecrãs | C8: 5 | D8: Acima das páginas incluídas, cada página soma horas.
B9: Nível de design | C9: Semi-custom (base + identidade)
B10: Nº de idiomas | C10: 1 | D10: Cada idioma extra acresce % em frontend, QA, conteúdos e SEO.
B11: Nº de integrações externas | C11: 0 | D11: Pagamentos, CRM, ERP, APIs, newsletter…
B12: Conteúdos (textos / imagens) | C12: Cliente fornece textos e imagens
B13: SEO | C13: SEO base (on-page + meta)
B14: Prazo / urgência | C14: Normal (prazo confortável)
B15: Perfil de cliente | C15: PME
B16: Desconto comercial | C16: 0 | D16: Usar com critério: sai direto da margem.
B17: Custos externos a repassar | C17: 0 | D17: Licenças, fotografia, domínio, 1º ano de alojamento.
B19: 2. ESFORÇO E PRAZO
B20: Horas estimadas (com gestão e buffer) | C20: =Detalhe!D16
B21: Prazo de produção estimado | C21: =ROUNDUP(Detalhe!D16/Parametros!$B$17,0)
B22: Preço base do modelo | C22: =Detalhe!F20
B24: 3. ESCALÕES DE PREÇO
B25: Escalão | C25: Sem IVA | D25: Com IVA | E25: Quando usar
B26: Preço Mínimo | C26: =MAX(VLOOKUP($C$6,Parametros!$A$27:$I$33,9,FALSE),ROUND($C$22*Parametros!$B$18/Parametros!$B$23,0)*Parametros!$B$23)*(1-$C$16)+$C$17 | D26: =C26*(1+Parametros!$B$24) | E26: Piso de negociação. Abaixo disto, recusar o projeto.
B27: Preço Recomendado | C27: =MAX(VLOOKUP($C$6,Parametros!$A$27:$I$33,9,FALSE),ROUND($C$22*1/Parametros!$B$23,0)*Parametros!$B$23)*(1-$C$16)+$C$17 | D27: =C27*(1+Parametros!$B$24) | E27: Valor a apresentar por defeito na proposta.
B28: Preço Premium | C28: =MAX(VLOOKUP($C$6,Parametros!$A$27:$I$33,9,FALSE),ROUND($C$22*Parametros!$B$19/Parametros!$B$23,0)*Parametros!$B$23)*(1-$C$16)+$C$17 | D28: =C28*(1+Parametros!$B$24) | E28: Prioridade na fila, revisões extra e acompanhamento próximo.
B29: Valor / hora efetivo (Recomendado) | C29: =IFERROR(($C$27-$C$17)/$C$20,0) | E29: Comparar com a tarifa alvo. Se descer muito, o desconto é excessivo.
B31: 4. MANUTENÇÃO MENSAL
B32: Plano Essencial | C32: =MAX(Parametros!$C$66,ROUND($C$27*Parametros!$B$66,0)) | D32: =C32*12 | E32: Alojamento, updates de segurança, backups, 1h/mês de alterações, resposta em 3 dias úteis.
B33: Plano Pro | C33: =MAX(Parametros!$C$67,ROUND($C$27*Parametros!$B$67,0)) | D33: =C33*12 | E33: Tudo do Essencial + monitorização, 3h/mês de alterações, relatório trimestral, resposta em 1 dia útil.
B34: Plano Premium | C34: =MAX(Parametros!$C$68,ROUND($C$27*Parametros!$B$68,0)) | D34: =C34*12 | E34: Tudo do Pro + 6h/mês de evolução, prioridade absoluta, SLA 4h úteis, reunião mensal.
B36: 5. PLANO DE PAGAMENTO (sobre o Preço Recomendado)
B37: Sinal — arranque | C37: 0.4 | D37: =$C$27*C37
B38: Aprovação do design / staging | C38: 0.3 | D38: =$C$27*C38
B39: Entrega e publicação | C39: 0.3 | D39: =$C$27*C39

Sheet Detalhe
A1: DETALHE DO CÁLCULO
A2: Folha de auditoria: mostra de onde vem cada hora e cada euro. Não requer edição.
A4: Fase | B4: Horas base | C4: Fator | D4: Horas ajustadas | E4: Tarifa €/h | F4: Valor
A5: Descoberta / Estratégia | B5: =VLOOKUP(Calculadora!$C$6,Parametros!$A$27:$I$33,2,FALSE) | C5: =VLOOKUP(Calculadora!$C$7,Parametros!$A$36:$B$39,2,FALSE) | D5: =B5*C5 | E5: =Parametros!$B$4 | F5: =D5*E5
A6: UX / Design | B6: =VLOOKUP(Calculadora!$C$6,Parametros!$A$27:$I$33,3,FALSE)+MAX(0,Calculadora!$C$8-VLOOKUP(Calculadora!$C$6,Parametros!$A$27:$I$33,8,FALSE))*Parametros!$B$20*0.4 | C6: =VLOOKUP(Calculadora!$C$7,Parametros!$A$36:$B$39,2,FALSE)*VLOOKUP(Calculadora!$C$9,Parametros!$A$42:$B$44,2,FALSE) | D6: =B6*C6 | E6: =Parametros!$B$5 | F6: =D6*E6
A7: Frontend | B7: =VLOOKUP(Calculadora!$C$6,Parametros!$A$27:$I$33,4,FALSE)+MAX(0,Calculadora!$C$8-VLOOKUP(Calculadora!$C$6,Parametros!$A$27:$I$33,8,FALSE))*Parametros!$B$20*0.6 | C7: =VLOOKUP(Calculadora!$C$7,Parametros!$A$36:$B$39,2,FALSE)*VLOOKUP(Calculadora!$C$9,Parametros!$A$42:$B$44,2,FALSE)*(1+MAX(0,Calculadora!$C$10-1)*Parametros!$B$21) | D7: =B7*C7 | E7: =Parametros!$B$6 | F7: =D7*E7
A8: Backend / CMS | B8: =VLOOKUP(Calculadora!$C$6,Parametros!$A$27:$I$33,5,FALSE) | C8: =VLOOKUP(Calculadora!$C$7,Parametros!$A$36:$B$39,2,FALSE) | D8: =B8*C8 | E8: =Parametros!$B$7 | F8: =D8*E8
A9: Integrações / API | B9: =VLOOKUP(Calculadora!$C$6,Parametros!$A$27:$I$33,6,FALSE)+Calculadora!$C$11*Parametros!$B$22 | C9: =VLOOKUP(Calculadora!$C$7,Parametros!$A$36:$B$39,2,FALSE) | D9: =B9*C9 | E9: =Parametros!$B$8 | F9: =D9*E9
A10: QA / Testes | B10: =VLOOKUP(Calculadora!$C$6,Parametros!$A$27:$I$33,7,FALSE) | C10: =VLOOKUP(Calculadora!$C$7,Parametros!$A$36:$B$39,2,FALSE)*(1+MAX(0,Calculadora!$C$10-1)*Parametros!$B$21) | D10: =B10*C10 | E10: =Parametros!$B$9 | F10: =D10*E10
A11: Produção de conteúdos | B11: =VLOOKUP(Calculadora!$C$12,Parametros!$A$57:$B$58,2,FALSE) | C11: =(1+MAX(0,Calculadora!$C$10-1)*Parametros!$B$21) | D11: =B11*C11 | E11: =Parametros!$B$11 | F11: =D11*E11
A12: SEO | B12: =VLOOKUP(Calculadora!$C$13,Parametros!$A$61:$B$63,2,FALSE) | C12: =(1+MAX(0,Calculadora!$C$10-1)*Parametros!$B$21) | D12: =B12*C12 | E12: =Parametros!$B$12 | F12: =D12*E12
A13: Subtotal técnico | D13: =SUM(D5:D12) | F13: =SUM(F5:F12)
A14: Gestão de projeto | D14: =D13*Parametros!$B$15 | E14: =Parametros!$B$10 | F14: =D14*E14
A15: Buffer de risco | D15: =(D13+D14)*Parametros!$B$16 | F15: =(F13+F14)*Parametros!$B$16
A16: TOTAL | D16: =D13+D14+D15 | F16: =F13+F14+F15
A18: Fator de urgência | D18: =VLOOKUP(Calculadora!$C$14,Parametros!$A$47:$B$49,2,FALSE)
A19: Fator de perfil de cliente | D19: =VLOOKUP(Calculadora!$C$15,Parametros!$A$52:$B$54,2,FALSE)
A20: PREÇO BASE (antes de escalões) | F20: =F16*D18*D19

Sheet Parametros
A1: PARÂMETROS DO MODELO esDEV
A2: Toda a calibração do preço vive nesta folha. Altera aqui — nunca nas fórmulas da folha Calculadora.
A3: TARIFAS POR FASE (€ / hora)
A4: Descoberta / Estratégia | B4: 40
A5: UX / Design | B5: 45
A6: Frontend | B6: 45
A7: Backend / CMS | B7: 50
A8: Integrações / API | B8: 55
A9: QA / Testes | B9: 35
A10: Gestão de projeto | B10: 40
A11: Produção de conteúdos | B11: 40
A12: SEO | B12: 45
A14: CONSTANTES DE CÁLCULO
A15: Gestão de projeto (% das horas técnicas) | B15: 0.15
A16: Buffer de risco (% sobre horas e valor) | B16: 0.1
A17: Capacidade de produção (h / semana) | B17: 25
A18: Fator do Preço Mínimo | B18: 0.85
A19: Fator do Preço Premium | B19: 1.3
A20: Horas por página / ecrã extra | B20: 3
A21: Acréscimo por idioma adicional (%) | B21: 0.12
A22: Horas por integração externa extra | B22: 6
A23: Arredondamento do preço final (€) | B23: 25
A24: IVA | B24: 0.23
A26: Tipo de projeto | B26: Descoberta | C26: UX / Design | D26: Frontend | E26: Backend | F26: Integrações | G26: QA | H26: Páginas incl. | I26: Preço mínimo
A27: Landing page (1 página) | B27: 2 | C27: 6 | D27: 14 | E27: 0 | F27: 2 | G27: 3 | H27: 1 | I27: 450
A28: Website institucional (até 5 páginas) | B28: 4 | C28: 12 | D28: 28 | E28: 4 | F28: 4 | G28: 6 | H28: 5 | I28: 950
A29: Website + Blog / CMS | B29: 6 | C29: 16 | D29: 40 | E29: 16 | F29: 6 | G29: 10 | H29: 8 | I29: 1500
A30: Loja online (e-commerce) | B30: 10 | C30: 24 | D30: 70 | E30: 40 | F30: 20 | G30: 18 | H30: 10 | I30: 2900
A31: Web app / Dashboard | B31: 14 | C31: 24 | D31: 90 | E31: 90 | F31: 24 | G31: 28 | H31: 8 | I31: 4500
A32: Automação / Integrações | B32: 8 | C32: 4 | D32: 10 | E32: 40 | F32: 40 | G32: 12 | H32: 1 | I32: 1500
A33: Redesign / Recuperação de site | B33: 4 | C33: 10 | D33: 24 | E33: 10 | F33: 6 | G33: 8 | H33: 5 | I33: 900
A35: NÍVEL DE COMPLEXIDADE | B35: Fator
A36: Simples — pouco conteúdo, sem lógica | B36: 0.85
A37: Média — padrão de mercado | B37: 1
A38: Alta — regras de negócio próprias | B38: 1.35
A39: Muito alta — crítico / à medida | B39: 1.7
A41: NÍVEL DE DESIGN | B41: Fator
A42: Template adaptado | B42: 0.7
A43: Semi-custom (base + identidade) | B43: 1
A44: 100% à medida | B44: 1.4
...

Sheet Proposta
B1: RESUMO PARA PROPOSTA
B2: Pronto a copiar para o e-mail ou documento de proposta.
B4: Projeto | C4: =Calculadora!$C$5
B5: Âmbito | C5: =Calculadora!$C$6&" · "&Calculadora!$C$7
B6: Dimensão | C6: =Calculadora!$C$8&" páginas/ecrãs · "&Calculadora!$C$10&" idioma(s) · "&Calculadora!$C$11&" integração(ões)"
B7: Design | C7: =Calculadora!$C$9
B8: Conteúdos | C8: =Calculadora!$C$12
B9: SEO | C9: =Calculadora!$C$13
B10: Esforço estimado | C10: =TEXT(Calculadora!$C$20,"#,##0")&" horas"
B11: Prazo de produção | C11: =Calculadora!$C$21&" semanas após aprovação"
B13: INVESTIMENTO
B14: Valor do projeto (s/ IVA) | C14: =Calculadora!$C$27
B15: Valor com IVA à taxa legal | C15: =Calculadora!$D$27
B16: Manutenção mensal recomendada (Pro) | C16: =Calculadora!$C$33
B18: Condições de pagamento
B19: =TEXT(Calculadora!$D$37,"#,##0 €")&" no arranque · "&TEXT(Calculadora!$D$38,"#,##0 €")&" na aprovação do design · "&TEXT(Calculadora!$D$39,"#,##0 €")&" na entrega"
B21: Notas
B22: • Proposta válida por 30 dias.
B23: • Inclui duas rondas de revisão por fase; revisões adicionais são orçamentadas à hora.
B24: • Alterações de âmbito após aprovação seguem novo orçamento.
B25: • Licenças, alojamento e domínio são custos de terceiros, faturados a preço de custo.
